<!DOCTYPE html>
<html lang="zh">
<head>
    <meta charset="UTF-8">
    <title>13-promise的几个关键问题6</title>
</head>
<body>
<script src="https://cdn.bootcdn.net/ajax/libs/jquery/3.6.0/jquery.min.js"></script>
<script>
    /*
        promise错误穿透：
            (1)当使用promise的then链式调用时, 可以在最后用catch指定一个失败的回调,
            (2)前面任何操作出了错误, 都会传到最后失败的回调中处理了
        备注：如果不存在then的链式调用，就不需要考虑then的错误穿透。
    */
    function sendAjax(url, data) {
        return new Promise((resolve, reject) => {
            //实例xhr
            const xhr = new XMLHttpRequest();
            //绑定监听
            xhr.onreadystatechange = () => {
                if (xhr.readyState === 4) {
                    if (xhr.status >= 200 && xhr.status < 300) {
                        resolve(xhr.response);
                    } else {
                        reject(`请求出了点问题`);
                    }
                }
            }
            //整理参数
            let str = '';
            for (let key in data) {
                str += `${key}=${data[key]}&`;
            }
            str = str.slice(0, -1);

            xhr.open('GET', url + '?' + str);
            xhr.responseType = 'json';
            xhr.send();
        });
    }

    //发送第一次请求
    sendAjax('https://api.apiopen.top/getJoke', {page: 1})
        .then(
            value => {
                console.log('第1次请求成功了', value);
                //发送第二次请求
                return sendAjax('https://api.apiopen.top/getJoke2', {page: 1});
            },
            // reason => {console.log('第1次请求失败了', reason);return new Promise(() => {});}
        )
        .then(
            value => {
                console.log('第2次请求成功了', value);
                //发送第三次请求
                return sendAjax('https://api.apiopen.top/getJoke', {page: 1});
            },
            // reason => {console.log('第2次请求失败了', reason);return new Promise(() => {});}
        )
        .then(
            value => {
                console.log('第3次请求成功了', value);
            },
            // reason => {console.log('第3次请求失败了', reason);}
        )
        .catch(
            reason => {
                console.log(reason);
            }
        )

    //另一个例子演示错误的穿透
    const p = new Promise((resolve, reject) => {
        setTimeout(() => {
            resolve(-1)
        }, 500)
    })

    p.then(
        value => {
            console.log('成功了' + value)
            return 'b';
        },
        reason => {
            throw reason
        }//底层帮我们补上的这个失败的回调
    ).then(
        value => {
            console.log('成功了' + value)
            return Promise.reject(-3)
        },
        reason => {
            throw reason
        }//底层帮我们补上的这个失败的回调
    ).catch(
        reason => {
            console.log('失败了' + reason)
        }
    )


</script>
</body>
</html>